Workbook

Sheet MATERIAS PRIMAS
A1: CÓDIGO | B1: DESCRIPCIÓN | C1: CATIDAD | D1: % | E1: SEP - COP / Kg | F1: SEP - COP / APP | G1: AGO - COP / Kg | H1: AGO - COP / APP | I1: %
A2: MPPC077 | B2: TAROMA HAM. BOLSA X 5 KILOS | C2: 0.00091049995 | D2: =(C2*100)/#REF! -> #REF! | E2: 70021 | F2: =E2*C2 -> 63.754117 | G2: 65950 | H2: =G2*C2 -> 60.047472 | I2: =((E2/G2)*100)-100 -> 6.1728582
A3: MPCC026 | B3: TOCINO | C3: 0.032673256 | D3: 24.024453 | E3: 7029 | F3: =E3*C3 -> 229.66032 | G3: 6648 | H3: =G3*C3 -> 217.21181 | I3: =((E3/G3)*100)-100 -> 5.7310469
A4: MPPS102 | B4: REACTYNSH2 TRASGLUTAMINASA BOLSA X 1 KG | C4: 8.9915526e-05 | D4: =(C4*100)/#REF! -> #REF! | E4: 153185 | F4: =E4*C4 -> 13.77371 | G4: 145309 | H4: =G4*C4 -> 13.065535 | I4: =((E4/G4)*100)-100 -> 5.4201736
A5: MPPD172 | B5: MEZCLA DE FOSFATOS (CARFOSEL 996). SACO X 25 KILOS. | C5: 0.0011469276 | D5: =(C5*100)/#REF! -> #REF! | E5: 16795 | F5: =E5*C5 -> 19.26265 | G5: 16110 | H5: =G5*C5 -> 18.477004 | I5: =((E5/G5)*100)-100 -> 4.2520174
A6: MPPA144 | B6: ALMIDON DE PAPA SACO X 25 KILOS . | C6: 0.056625423 | D6: =(C6*100)/#REF! -> #REF! | E6: 5975 | F6: =E6*C6 -> 338.3369 | G6: 5761 | H6: =G6*C6 -> 326.21906 | I6: =((E6/G6)*100)-100 -> 3.7146329
A7: MPPD160 | B7: MEZCLA DE FOSFATOS (CARNAL 961). SACO X 25 KILOS. | C7: 0.00072081065 | D7: =(C7*100)/#REF! -> #REF! | E7: 21400 | F7: =E7*C7 -> 15.425348 | G7: 20650 | H7: 14.88474 | I7: =((E7/G7)*100)-100 -> 3.6319613
A8: MPCP037 | B8: PIEL DE POLLO NACIONAL | C8: 0.11336516 | D8: 11.336516 | E8: 3160 | F8: =E8*C8 -> 358.23389 | G8: 3067 | H8: =G8*C8 -> 347.69093 | I8: =((E8/G8)*100)-100 -> 3.0322791
A9: MPPA154 | B9: PROTEÍNA DE SOYA AL 70%. WILCON SJ. SACO X 20 KILOS | C9: 0.007863389 | D9: =(C9*100)/#REF! -> #REF! | E9: 16084 | F9: =E9*C9 -> 126.47475 | G9: 15638 | H9: 122.96768 | I9: =((E9/G9)*100)-100 -> 2.8520271
A10: MPPA168 | B10: PROTEÍNA COLAGÉNICA COLLAPRO P -950. SACO X 12,5 KILOS. | C10: 0.0003308756 | D10: =(C10*100)/#REF! -> #REF! | E10: 33158 | F10: =E10*C10 -> 10.971173 | G10: 32239 | H10: =G10*C10 -> 10.667098 | I10: =((E10/G10)*100)-100 -> 2.8505847
A11: MPPO142 | B11: COLOR NATURAL HEMOGLOBINA. I RED. BOLSA X 1 KILO. | C11: 8.9720613e-05 | D11: 0.065971039 | E11: 51477 | F11: =E11*C11 -> 4.618548 | G11: 50051 | H11: =G11*C11 -> 4.4906064 | I11: =((E11/G11)*100)-100 -> 2.8490939
A12: MPPH147 | B12: HUMO TRUSMOKE OIL EX. GARRAFA X 20 KG | C12: 0.00049154041 | D12: =(C12*100)/#REF! -> #REF! | E12: 40689 | F12: =E12*C12 -> 20.000288 | G12: 39563 | H12: =G12*C12 -> 19.446813 | I12: =((E12/G12)*100)-100 -> 2.8460936
A13: 30017 | B13: SALCHICHÓN AUTÉNTICO X 225 GRAMOS | C13: 1 | D13: =(C13*100)/#REF! -> #REF! | E13: 1385 | F13: =E13*C13 -> 1385 | G13: 1347 | H13: =G13*C13 -> 1347 | I13: =((E13/G13)*100)-100 -> 2.8210839
A14: MPPA122 | B14: PROTEÍNA DE SOYA AL 70%. ARCON T (Hojuelas). SACO X 11.34 KILOS | C14: 0.010857716 | D14: =(C14*100)/#REF! -> #REF! | E14: 16680 | F14: =E14*C14 -> 181.1067 | G14: 16262 | H14: =G14*C14 -> 176.56817 | I14: =((E14/G14)*100)-100 -> 2.5704095
A15: MIPS003 | B15: GRANULOS DE PROTEÍNA. CANASTA X 25 KILOS. | C15: 0.025856368 | D15: 4.9723784 | E15: 6260 | F15: =E15*C15 -> 161.86086 | G15: 6198 | H15: =G15*C15 -> 160.25777 | I15: =((E15/G15)*100)-100 -> 1.0003227
A16: 30018 | B16: SALCHICÓN DE POLLO X 225 GRAMOS | C16: 1 | D16: =(C16*100)/#REF! -> #REF! | E16: 1347 | F16: =E16*C16 -> 1347 | G16: 1336 | H16: =G16*C16 -> 1336 | I16: =((E16/G16)*100)-100 -> 0.82335329
A17: 10090O | B17: SALCHICHA CLASICA FAIZAN X 225 GRAMOS OFERTA | C17: 1 | D17: =(C17*100)/#REF! -> #REF! | E17: 2310 | F17: =E17*C17 -> 2310 | G17: 2293 | H17: =G17*C17 -> 2293 | I17: =((E17/G17)*100)-100 -> 0.74138683
A18: MPCP044 | B18: PASTA DE POLLO NACIONAL ALIPAQ | C18: 0.042469067 | D18: =(C18*100)/#REF! -> #REF! | E18: 5484 | F18: =E18*C18 -> 232.90036 | G18: 5453 | H18: =G18*C18 -> 231.58382 | I18: =((E18/G18)*100)-100 -> 0.56849441
A19: MPPN323 | B19: CONSERVANTE INBAC ACN/NA. CAJA X 25 KILOS. | C19: 0.0056625423 | D19: =(C19*100)/#REF! -> #REF! | E19: 59418 | F19: =E19*C19 -> 336.45694 | G19: 59227 | H19: =G19*C19 -> 335.37539 | I19: =((E19/G19)*100)-100 -> 0.32248805
A20: MPPS090 | B20: AZÚCAR REFINADA. SACO X 50 KILOS. | C20: 0.0030528513 | D20: =(C20*100)/#REF! -> #REF! | E20: 4915 | F20: =E20*C20 -> 15.004764 | G20: 4908 | H20: =G20*C20 -> 14.983394 | I20: =((E20/G20)*100)-100 -> 0.14262429
A21: MPPO135 | B21: COLOR NATURAL NARANJA LIQUIDO RA 40 - 3 9827 AF. GALÓN x 4 KILOS. | C21: 0.00017645054 | D21: 0.12974304 | E21: 53618 | F21: =E21*C21 -> 9.460925 | G21: 53617 | H21: =G21*C21 -> 9.4607485 | I21: =((E21/G21)*100)-100 -> 0.0018650801
A22: MPPC109 | B22: CONDIMENTO AJIAROMA M - C100. BOLSA X 1 KILO. | C22: 0.0057677009 | D22: 0.57677009 | E22: 62000 | F22: =E22*C22 -> 357.59745 | G22: 62000 | H22: =G22*C22 -> 357.59745 | I22: =((E22/G22)*100)-100 -> 0
A23: MPII311 | B23: AGUA POTABLE. | C23: 0.13988295 | D23: 26.900567 | E23: 7 | F23: =E23*C23 -> 0.97918065 | G23: 7 | H23: =G23*C23 -> 0.97918065 | I23: =((E23/G23)*100)-100 -> 0
A24: MPPS104 | B24: AJO MOLIDO DESHIDRATADO B. 1. CAJA X 20 KILOS. (LA CAMPANA) | C24: 0.00013572423 | D24: =(C24*100)/#REF! -> #REF! | E24: 30713 | F24: =E24*C24 -> 4.1684982 | G24: 30713 | H24: =G24*C24 -> 4.1684982 | I24: =((E24/G24)*100)-100 -> 0
B25: APANADO | C25: 0.0792 | D25: 12 | E25: 7900 | F25: 625.68 | G25: 7900 | H25: 625.68 | I25: 0
A26: MPPC120 | B26: AROMA SALCHICHON TRADICIONAL 84987B. GARRAFA X 5 KILOS | C26: 0.0038752757 | D26: =(C26*100)/#REF! -> #REF! | E26: 35100 | F26: =E26*C26 -> 136.02218 | G26: 35100 | H26: =G26*C26 -> 136.02218 | I26: =((E26/G26)*100)-100 -> 0
A27: MPPD168 | B27: CARRAGENINA CEAMGEL M 9396. SACO X 25 KILOS. | C27: 0.0015825356 | D27: =(C27*100)/#REF! -> #REF! | E27: 62980 | F27: =E27*C27 -> 99.668094 | G27: 62980 | H27: =G27*C27 -> 99.668094 | I27: =((E27/G27)*100)-100 -> 0
A28: MPPS153 | B28: CEBOLLA EN POLVO B.1. CAJA X 20 KILOS. (LA CAMPANA) | C28: 0.00051875753 | D28: =(C28*100)/#REF! -> #REF! | E28: 24619 | F28: =E28*C28 -> 12.771292 | G28: 24619 | H28: =G28*C28 -> 12.771292 | I28: =((E28/G28)*100)-100 -> 0
A29: MPLO211 | B29: COLOR CARAMELO. GARRAFA X 20 KILOS. | C29: 0.0022921844 | D29: =(C29*100)/#REF! -> #REF! | E29: 4561 | F29: =E29*C29 -> 10.454653 | G29: 4561 | H29: =G29*C29 -> 10.454653 | I29: =((E29/G29)*100)-100 -> 0
A30: MPPO134 | B30: COLOR LOY.(NARAN. LIQ. A10-1). TARRO X 1 KILO. | C30: 0.00023177825 | D30: 0.17042518 | E30: 39122 | F30: =E30*C30 -> 9.0676287 | G30: 39122 | H30: =G30*C30 -> 9.0676287 | I30: =((E30/G30)*100)-100 -> 0
A31: MPLO215 | B31: COLOR NATURAL NARANJA PR801 WD. GARRAFA X 10 KILOS. | C31: 9.0600677e-05 | D31: =(C31*100)/#REF! -> #REF! | E31: 169210 | F31: =E31*C31 -> 15.33054 | G31: 169210 | H31: =G31*C31 -> 15.33054 | I31: =((E31/G31)*100)-100 -> 0
A32: MPLO214 | B32: COLOR NATURAL ROJO AC305RWS. GARRAFA X 4 KILOS. | C32: 0.00045300338 | D32: =(C32*100)/#REF! -> #REF! | E32: 121899 | F32: =E32*C32 -> 55.220659 | G32: 121899 | H32: =G32*C32 -> 55.220659 | I32: =((E32/G32)*100)-100 -> 0
A33: MPPS157 | B33: COMINO MOLIDO B.1. BOLSA X 1 KILO. (LA CAMPANA) | C33: 0.00011389446 | D33: =(C33*100)/#REF! -> #REF! | E33: 32511 | F33: =E33*C33 -> 3.7028227 | G33: 32511 | H33: =G33*C33 -> 3.7028227 | I33: =((E33/G33)*100)-100 -> 0
A34: MPPS152 | B34: DEXTROSA. BOLSA X 1 KILO. | C34: 0.0033975254 | D34: =(C34*100)/#REF! -> #REF! | E34: 10972 | F34: =E34*C34 -> 37.277648 | G34: 10972 | H34: =G34*C34 -> 37.277648 | I34: =((E34/G34)*100)-100 -> 0
A35: MPCC012 | B35: EMULSION (Piel de Cerdo) - Tocino Partes Magras | C35: 0.0965038 | D35: =(C35*100)/#REF! -> #REF! | E35: 1500 | F35: =E35*C35 -> 144.7557 | G35: 1500 | H35: =G35*C35 -> 144.7557 | I35: =((E35/G35)*100)-100 -> 0
A36: MPCC012 | B36: EMULSIÓN ABLANDADA. Disco 6 mm | C36: 0.038784552 | D36: 7.4585677 | E36: 1500 | F36: =E36*C36 -> 58.176828 | G36: 1500 | H36: =G36*C36 -> 58.176828 | I36: =((E36/G36)*100)-100 -> 0
A37: MPPO140 | B37: ENTURBIANTE EN POLVO DPA X 1 KILO | C37: 0.003049589 | D37: 0.3049589 | E37: 50633 | F37: =E37*C37 -> 154.40984 | G37: 50633 | H37: =G37*C37 -> 154.40984 | I37: =((E37/G37)*100)-100 -> 0
A38: MPPD161 | B38: ERITORBATO DE SODIO. CAJA X 25 KILOS. | C38: 0.00056625423 | D38: =(C38*100)/#REF! -> #REF! | E38: 26800 | F38: =E38*C38 -> 15.175613 | G38: 26800 | H38: =G38*C38 -> 15.175613 | I38: =((E38/G38)*100)-100 -> 0
A39: MPPA134 | B39: EXTRACTO PROTEICO LC 300. Saco x 25 kg. | C39: 0.0090600677 | D39: =(C39*100)/#REF! -> #REF! | E39: 19616 | F39: =E39*C39 -> 177.72229 | G39: 19616 | H39: =G39*C39 -> 177.72229 | I39: =((E39/G39)*100)-100 -> 0
A40: MPCC019 | B40: GRASA EMPELLA | C40: 0.028673191 | D40: =(C40*100)/#REF! -> #REF! | E40: 4000 | F40: =E40*C40 -> 114.69276 | G40: 4000 | H40: =G40*C40 -> 114.69276 | I40: =((E40/G40)*100)-100 -> 0
...

Sheet MATERIAL DE EMPAQUE
A1: CÓDIGO | B1: DESCRIPCIÓN | C1: CATIDAD | D1: SEP - COP / Kg | E1: SEP - COP / APP | F1: AGO - COP / Kg | G1: AGO - COP / APP | H1: %
A2: MPEP405 | B2: Grapas Poly-Clip GMBH 15-08 5 x 1,5 Carrete x 5,500 unidades | C2: 2 | D2: 27 | E2: =D2*C2 -> 54 | F2: 22 | G2: 44 | H2: =((D2/F2)*100)-100 -> 22.727273
A3: MPEP434 | B3: Grapas Poly-Clip GMBH R-ID M 07-150 Carrete x 6,800 unidades | C3: 2 | D3: 27 | E3: =D3*C3 -> 54 | F3: 22 | G3: =F3*C3 -> 44 | H3: =((D3/F3)*100)-100 -> 22.727273
A4: MPES972 | B4: Caja Koba Salchichón Tradicional Viandé x 500 gramos (15 unidades) | C4: 0.046 | D4: 1624 | E4: =D4*C4 -> 74.704 | F4: 1353 | G4: =F4*C4 -> 62.238 | H4: =((D4/F4)*100)-100 -> 20.029564
A5: MPES974 | B5: Caja Koba Salchicha Tradicional Viandé x 450 gramos. (22 unidades) | C5: 0.045 | D5: 1816 | E5: =D5*C5 -> 81.72 | F5: 1513 | G5: =F5*C5 -> 68.085 | H5: =((D5/F5)*100)-100 -> 20.026438
A6: MPES202 | B6: Lámina Inferior Sudpack GVP 130-323 mm (5.0 mils). 1 Rollo x 350 metros | C6: 0.04 | D6: 1350 | E6: =D6*C6 -> 54 | F6: 1125 | G6: =F6*C6 -> 45 | H6: =((D6/F6)*100)-100 -> 20
A7: MPES186 | B7: Lámina Inferior Sudpack GVP 130-423 mm (5.0 mils). 1 Rollo x 350 metros | C7: 0.14 | D7: 1464 | E7: =D7*C7 -> 204.96 | F7: 1323 | G7: =F7*C7 -> 185.22 | H7: =((D7/F7)*100)-100 -> 10.657596
A8: MPES251 | B8: Lámina Superior Impresa Mega Combo Faizán x 900 gramos | C8: 0.0109 | D8: 26300 | E8: =D8*C8 -> 286.67 | F8: 23900 | G8: =F8*C8 -> 260.51 | H8: =((D8/F8)*100)-100 -> 10.041841
A9: MPEP969 | B9: Clips HC25-3218T. Carrete x 2,400 unidades. | C9: 0.091 | D9: 57 | E9: =D9*C9 -> 5.187 | F9: 52 | G9: =F9*C9 -> 4.732 | H9: =((D9/F9)*100)-100 -> 9.6153846
A10: MPEP424 | B10: Fibrosa FVP CLS 140 B5 4 H5 Natural Corrugado. (Viandé) | C10: 0.0575 | D10: 4053 | E10: =D10*C10 -> 233.0475 | F10: 3712 | G10: =F10*C10 -> 213.44 | H10: =((D10/F10)*100)-100 -> 9.1864224
A11: MPES994 | B11: Tubular Salchichón Tradicional x 750 Gramos Cal 44 | C11: 0.5 | D11: 606 | E11: =D11*C11 -> 303 | F11: 565 | G11: =F11*C11 -> 282.5 | H11: =((D11/F11)*100)-100 -> 7.2566372
A12: MPEP380 | B12: Funda Celulosa Nojax 20 x 100 Tubo x 30,48 metros. Caja x 200 tubos x 6,096 metros | C12: 9 | D12: 204 | E12: =D12*C12 -> 1836 | F12: 192 | G12: =F12*C12 -> 1728 | H12: =((D12/F12)*100)-100 -> 6.25
A13: MPES207 | B13: Tubular Salchichón Pollo Bakel x 225 Gramos. Cal 40 | C13: 0.22 | D13: 512 | E13: =D13*C13 -> 112.64 | F13: 491 | G13: =F13*C13 -> 108.02 | H13: =((D13/F13)*100)-100 -> 4.2769857
A14: MPES208 | B14: Tubular Salchichón Tradicional Viande x 500 Gramos. Cal 44 | C14: 0.4 | D14: 522 | E14: =D14*C14 -> 208.8 | F14: 504 | G14: =F14*C14 -> 201.6 | H14: =((D14/F14)*100)-100 -> 3.5714286
A15: MPES133 | B15: Tubular Salchichón Cervecero 1.500 gramos | C15: 0.7 | D15: 589 | E15: =D15*C15 -> 412.3 | F15: 569 | G15: =C15*F15 -> 398.3 | H15: =((D15/F15)*100)-100 -> 3.5149385
A16: MPES182 | B16: Lámina Superior Mortadela Seleccionada Viandé x 225 gramos x 17 unidades. Ancho = 415 mm. (Pet / coextrusión HBA 70 micras). | C16: 0.073 | D16: 908 | E16: =D16*C16 -> 66.284 | F16: 878 | G16: 64.094 | H16: =((D16/F16)*100)-100 -> 3.4168565
A17: MPES183 | B17: Lámina Superior Impresa Salchicha Viandé x 225 gramos x 8 unidades. Ancho = 415 mm. (Pet / coextrusión HBA 70 micras). | C17: 0.073 | D17: 908 | E17: =D17*C17 -> 66.284 | F17: 880 | G17: =F17*C17 -> 64.24 | H17: =((D17/F17)*100)-100 -> 3.1818182
A18: MPEP410 | B18: Funda Celulosa 23 USA x 4 CE S (Cartón x 7.680 metros x 300 tubos,C/tubo x 25.6 metros. 6 caddy x 50 tubos) | C18: 1.76 | D18: 243 | E18: =D18*C18 -> 427.68 | F18: 236 | G18: =F18*C18 -> 415.36 | H18: =((D18/F18)*100)-100 -> 2.9661017
A19: MPES100 | B19: Tubular Salchichón Cervecero x 750 gramos | C19: 0.35 | D19: 606 | E19: =D19*C19 -> 212.1 | F19: 589 | G19: =F19*C19 -> 206.15 | H19: =((D19/F19)*100)-100 -> 2.8862479
A20: MPES106 | B20: Tubular Salchichón Cervecero x 500 gramos | C20: 0.3 | D20: 686 | E20: =D20*C20 -> 205.8 | F20: 667 | G20: 192.9 | H20: =((D20/F20)*100)-100 -> 2.8485757
A21: MPES462 | B21: Lámina Inferior Modflex 180 micras (280m/rollo). 7 mils - 423 mm | C21: 0.14 | D21: 2388 | E21: =D21*C21 -> 334.32 | F21: 2322 | G21: =F21*C21 -> 325.08 | H21: =((D21/F21)*100)-100 -> 2.8423773
A22: MPES161 | B22: Tubular Salchichón Pollo X 225 gramos Cal 40 | C22: 0.22 | D22: 581 | E22: =D22*C22 -> 127.82 | F22: 565 | G22: =F22*C22 -> 124.3 | H22: =((D22/F22)*100)-100 -> 2.8318584
A23: MPES162 | B23: Tubular Salchichón Auténtico x 225 gramos. Cal 40 | C23: 0.22 | D23: 581 | E23: =D23*C23 -> 127.82 | F23: 565 | G23: =F23*C23 -> 124.3 | H23: =((D23/F23)*100)-100 -> 2.8318584
A24: MPEP355 | B24: Funda Celulosa 18 x 100 (Cartón x 9.144 metros x 300 tubos,C/tubo x 30.48 metros. 6 caddy x 50 tubos) | C24: 4.4 | D24: 222 | E24: =D24*C24 -> 976.8 | F24: 216 | G24: =F24*C24 -> 950.4 | H24: =((D24/F24)*100)-100 -> 2.7777778
A25: MPES155 | B25: Etiqueta Megasalchicha x 560 gramos x 6 unidades | C25: 1 | D25: 115 | E25: =D25*C25 -> 115 | F25: 112 | G25: =F25*C25 -> 112 | H25: =((D25/F25)*100)-100 -> 2.6785714
A26: MPES206 | B26: Tubular Salchichón Pollo Bakel x 500 Gramos. Cal 44 | C26: 0.4 | D26: 535 | E26: =D26*C26 -> 214 | F26: 522 | G26: 208.8 | H26: =((D26/F26)*100)-100 -> 2.4904215
A27: MPEP955 | B27: Polijax 20 X 110 Impresa. Tubo x 33.53 metros. Caja x 300 tubos x 10.058 metros | C27: 1.68 | D27: 255 | E27: =D27*C27 -> 428.4 | F27: 249 | G27: =F27*C27 -> 418.32 | H27: =((D27/F27)*100)-100 -> 2.4096386
A28: MPEP973 | B28: Funda Celulosa 20 x 100 CE FP CLR | C28: 0.88 | D28: 225 | E28: =D28*C28 -> 198 | F28: 220 | G28: =F28*C28 -> 193.6 | H28: =((D28/F28)*100)-100 -> 2.2727273
A29: MPEP431 | B29: Fibrosa FVP CLS 95 B3 4 H3 Natural Corrugado. (Mortadela) | C29: 0.036 | D29: 3800 | E29: =D29*C29 -> 136.8 | F29: 3716 | G29: =F29*C29 -> 133.776 | H29: =((D29/F29)*100)-100 -> 2.2604952
A30: MPEP354 | B30: Funda Colageno NDX 26/60 (cartón x 4,718 metros x 258 tubos, C/tubo x 18.29 metros. 6 Caddy x 43 tubos C/U) | C30: 0.1818 | D30: 598 | E30: =D30*C30 -> 108.7164 | F30: 585 | G30: =F30*C30 -> 106.353 | H30: =((D30/F30)*100)-100 -> 2.2222222
A31: MPES964 | B31: Lámina Inferior Sudpack GVA 200 BT 323 MM (8.MILS) 1 Rollo x 300 metros | C31: 0.146 | D31: 2219 | E31: =D31*C31 -> 323.974 | F31: 2173 | G31: =F31*C31 -> 317.258 | H31: =((D31/F31)*100)-100 -> 2.1168891
A32: MPEP968 | B32: Fibrosa FVP CLS 95 B3 4 H3 Natural Corrugada x 25 metros. | C32: 0.036 | D32: 3800 | E32: =D32*C32 -> 136.8 | F32: 3742 | G32: =F32*C32 -> 134.712 | H32: =((D32/F32)*100)-100 -> 1.5499733
A33: MPES209 | B33: Tubular Salchichón Cervecero Viande x 225 Gramos. Cal 40 | C33: 0.22 | D33: 474 | E33: =D33*C33 -> 104.28 | F33: 470 | G33: =F33*C33 -> 103.4 | H33: =((D33/F33)*100)-100 -> 0.85106383
A34: MPES190 | B34: Lámina Superior Impresa Salchicha x 225 gramos x 9 unidades. Sin Código. Ancho = 415 mm. (Pet / coextrusión HBA 70 micras). | C34: 0.073 | D34: 1519 | E34: =D34*C34 -> 110.887 | F34: 1510 | G34: =F34*C34 -> 110.23 | H34: =((D34/F34)*100)-100 -> 0.59602649
A35: MPEP352 | B35: Multiflex 180 mm. Transparente sin impresión. Para Milanesa. | C35: 0.15 | D35: 795 | E35: =D35*C35 -> 119.25 | F35: 795 | G35: =F35*C35 -> 119.25 | H35: =((D35/F35)*100)-100 -> 0
A36: MPEP418 | B36: Funda Colágeno NDX F 25/50 Cierre de Bola x 258 Tubos | C36: 0.4545 | D36: 574 | E36: =D36*C36 -> 260.883 | F36: 574 | G36: =F36*C36 -> 260.883 | H36: =((D36/F36)*100)-100 -> 0
A37: MPEP956 | B37: Lazos Poly-Clip LTDA GSA22 Rollo x 3.500 unidades de Lazadas | C37: 1 | D37: 46 | E37: =D37*C37 -> 46 | F37: 46 | G37: =F37*C37 -> 46 | H37: =((D37/F37)*100)-100 -> 0
A38: MPEP963 | B38: FIBROSA T-SHIRR BTC CLR REG 1 1/2 x 150 35ST Smoke-E3 | C38: 0.03 | D38: 2510 | E38: =D38*C38 -> 75.3 | F38: 2510 | G38: =F38*C38 -> 75.3 | H38: =((D38/F38)*100)-100 -> 0
... A67: MPES959 | B67: Caja Hamburguesa x 2.700 gramos | C67: 1 | D67: 1022 | E67: =D67*C67 -> 1022 | F67: 1022 | G67: =F67*C67 -> 1022 | H67: =((D67/F67)*100)-100 -> 0
A68: MPES968 | B68: Caja Koba Salchichón de Pollo Brakel x 500 gramos (15 unidades) | C68: 0.046 | D68: 1624 | E68: =D68*C68 -> 74.704 | F68: 1624 | G68: 74.704 | H68: =((D68/F68)*100)-100 -> 0
...

Sheet MP OCT
B2: PRECIO MATERIAS PRIMAS - OCT 22
B4: GRUPO | C4: CÓDIGO | D4: DESCRIPCIÓN | E4: OCT - COP / UMB | F4: SEP - COP / UMB | G4: %
B5: AGUA POTABLE | C5: MPII311 | D5: AGUA POTABLE. | E5: 7 | F5: 7 | G5: =((E5/F5)*100)-100 -> 0
B6: AGUA POTABLE | C6: MPII310 | D6: HIELO EN ESCAMAS (BOLSA X 20 KILOS) | E6: 310 | F6: 310 | G6: =((E6/F6)*100)-100 -> 0
B7: ALMIDONES | C7: MPPA144 | D7: ALMIDON DE PAPA SACO X 25 KILOS . | E7: 6316.85 | F7: 5975 | G7: =((F7/E7)*100)-100 -> -5.4117163
B8: ANTIOXIDANTE | C8: MPPD161 | D8: ERITORBATO DE SODIO. CAJA X 25 KILOS. | E8: 26800 | F8: 26800 | G8: =((E8/F8)*100)-100 -> 0
B9: AROMAS Y SABORES | C9: MPPC077 | D9: TAROMA HAM. BOLSA X 5 KILOS | E9: 75475.71 | F9: 70021 | G9: =((F9/E9)*100)-100 -> -7.2271066
B10: AROMAS Y SABORES | C10: MPPC102 | D10: PREPARADO SABOR CHORIZO CERDO SEVILLA. PAQUETE X 4,8 KILOS | E10: 40125 | F10: 37500 | G10: =((F10/E10)*100)-100 -> -6.5420561
B11: AROMAS Y SABORES | C11: MPPC115 | D11: CONDIMENTO AJIAROMA M - M100. BOLSA X 1 KILO | E11: 65857 | F11: 65850 | G11: =((F11/E11)*100)-100 -> -0.01062909
B12: AROMAS Y SABORES | C12: MPPC094 | D12: ADITIVO BURGER MEAT 80-B NATUR. BOLSA X 5 KILOS. | E12: 11052 | F12: 11052 | G12: =((E12/F12)*100)-100 -> 0
B13: AROMAS Y SABORES | C13: MPPC120 | D13: AROMA SALCHICHON TRADICIONAL 84987B. GARRAFA X 5 KILOS | E13: 35100 | F13: 35100 | G13: =((E13/F13)*100)-100 -> 0
B14: AROMAS Y SABORES | C14: MPPC117 | D14: MEZCLA LIQUIDA PARA SABORIZAR SALCHICHA MANGUERA. BOLSA X 8 KILOS | E14: 29877 | F14: 29877 | G14: =((E14/F14)*100)-100 -> 0
B15: AROMAS Y SABORES | C15: MPPC112 | D15: MEZCLA LÍQUIDA PARA SABORIZAR SALCHICHA. BOLSA X 2.7 KILOS. CAJA X 24,3 KILOS | E15: 27308 | F15: 27308 | G15: =((E15/F15)*100)-100 -> 0
B16: AROMAS Y SABORES | C16: MPPC122 | D16: MEZCLA SABOR MORTADELA DROP TECH | E16: 32870 | F16: 32870 | G16: =((E16/F16)*100)-100 -> 0
B17: AROMAS Y SABORES | C17: MPPC075 | D17: PREPARADO SABOR CERVECERO NEO. BOLSA X 7,03 KILOS. | E17: 15516 | F17: 15516 | G17: =((E17/F17)*100)-100 -> 0
B18: AROMAS Y SABORES | C18: MPPC116 | D18: PREPARADO SABOR CERVECERO SV - GF. BOLSA X 6,55 KILOS | E18: 16071 | F18: 16071 | G18: =((E18/F18)*100)-100 -> 0
B19: AROMAS Y SABORES | C19: MPPC097 | D19: PREPARADO SABOR CHORIZO TERNERA SEVILLA X 3,83 KG | E19: 36457 | F19: 36457 | G19: =((E19/F19)*100)-100 -> 0
B20: AROMAS Y SABORES | C20: MPPC076 | D20: PREPARADO SABOR JAMON CALIFORNIAX 1 KG | E20: 8214 | F20: 8214 | G20: =((E20/F20)*100)-100 -> 0
B21: AROMAS Y SABORES | C21: MPLS190 | D21: PREPARADO SABOR JAMÓN T 3391 x 4 KG LÍQUIDO | E21: 21534 | F21: 21534 | G21: =((E21/F21)*100)-100 -> 0
B22: AROMAS Y SABORES | C22: MPPK174 | D22: SABOR CERDO COCIDO TECNAS X 1 Kg. | E22: 72924 | F22: 72924 | G22: =((E22/F22)*100)-100 -> 0
B23: AROMAS Y SABORES | C23: MPPC110 | D23: SABOR ITALIAN MORTADELA FLAVOUR SACO X 15 KILOS | E23: 64256 | F23: 64256 | G23: =((E23/F23)*100)-100 -> 0
B24: AROMAS Y SABORES | C24: MPPC119 | D24: SABORIZANTE A POLLO SV. BOLSA X 1 KILO | E24: 46385 | F24: 46385 | G24: =((E24/F24)*100)-100 -> 0
B25: AROMAS Y SABORES | C25: MPPC109 | D25: CONDIMENTO AJIAROMA M - C100. BOLSA X 1 KILO. | E25: 62000 | F25: 65857 | G25: =((F25/E25)*100)-100 -> 6.2209677
B26: AROMAS Y SABORES | C26: MPPC121 | D26: PREPARADO SABOR CERVECERO PREMIUM SV | E26: 16071 | F26: 21000 | G26: =((F26/E26)*100)-100 -> 30.670151
B27: BREADER | D27: APANADO | E27: 7900 | F27: 7900 | G27: =((E27/F27)*100)-100 -> 0
B28: CARNE DE CERDO | C28: MPCC034 | D28: PIERNA DE CERDO. Molienda x Disco Riñon | E28: 17600 | F28: 17440 | G28: =((F28/E28)*100)-100 -> -0.90909091
B29: CARNE DE CERDO | C29: MPCC010 | D29: BRAZUELO DE CERDO. | E29: 15045 | F29: 16500 | G29: =((F29/E29)*100)-100 -> 9.670987
B30: CARNE DE POLLO | C30: MPCP031 | D30: PASTA DE POLLO IMPORTADA | E30: 7012.5 | F30: 6993 | G30: =((F30/E30)*100)-100 -> -0.27807487
B31: CARNE DE POLLO | C31: MPCP058 | D31: CARNE OSCURA DE POLLO | E31: 6800 | F31: 6800 | G31: =((E31/F31)*100)-100 -> 0
B32: CARNE DE POLLO | C32: MPCP044 | D32: PASTA DE POLLO NACIONAL | E32: 5420 | F32: 5484 | G32: =((F32/E32)*100)-100 -> 1.1808118
B33: COLORANTES | C33: MPPO142 | D33: COLOR NATURAL HEMOGLOBINA. I RED. BOLSA X 1 KILO. | E33: 53429.29 | F33: 51477 | G33: =((F33/E33)*100)-100 -> -3.6539696
B34: COLORANTES | C34: MPLO211 | D34: COLOR CARAMELO. GARRAFA X 20 KILOS. | E34: 4561 | F34: 4561 | G34: =((E34/F34)*100)-100 -> 0
B35: COLORANTES | C35: MPPO134 | D35: COLOR LOY.(NARAN. LIQ. A10-1). TARRO X 1 KILO. | E35: 39122 | F35: 39122 | G35: =((E35/F35)*100)-100 -> 0
B36: COLORANTES | C36: MPLO215 | D36: COLOR NATURAL NARANJA PR801 WD. GARRAFA X 10 KILOS. | E36: 169210 | F36: 169210 | G36: =((E36/F36)*100)-100 -> 0
B37: COLORANTES | C37: MPPO135 | D37: COLOR NATURAL NARANJA LIQUIDO RA 40 - 3 9827 AF. GALÓN x 4 KILOS. | E37: 53618 | F37: 53618 | G37: =((E37/F37)*100)-100 -> 0
B38: COLORANTES | C38: MPLO214 | D38: COLOR NATURAL ROJO AC305RWS. GARRAFA X 4 KILOS. | E38: 121899 | F38: 121899 | G38: =((E38/F38)*100)-100 -> 0
B39: CONDIMENTOS Y ESPECIAS | C39: MPPS104 | D39: AJO MOLIDO DESHIDRATADO B. 1. CAJA X 20 KILOS. (LA CAMPANA) | E39: 30713 | F39: 30713 | G39: =((E39/F39)*100)-100 -> 0
B40: CONDIMENTOS Y ESPECIAS | C40: MPPS153 | D40: CEBOLLA EN POLVO B.1. CAJA X 20 KILOS. (LA CAMPANA). | E40: 24619 | F40: 24619 | G40: =((E40/F40)*100)-100 -> 0
B41: CONDIMENTOS Y ESPECIAS | C41: MPPS154 | D41: PIMIENTA MOLIDA BLANCA. BOLSA X 1 KILO. (TECNAS) | E41: 69401 | F41: 69401 | G41: =((E41/F41)*100)-100 -> 0
B42: CONDIMENTOS Y ESPECIAS | C42: MPPS095 | D42: PIMIENTA NEGRA MOLIDA. BOLSA X 1 KILO. (TECNAS) | E42: 43120 | F42: 43120 | G42: =((E42/F42)*100)-100 -> 0
...

Sheet ME OCT
B2: PRECIO MATERIAL DE EMPAQUE Y EMBUTIDO - OCT 22
B4: GRUPO | C4: CÓDIGO | D4: DESCRIPCIÓN | E4: OCT - COP / UMB | F4: SEP - COP / UMB | G4: %
B5: BOLSAS LAMINADAS | C5: MPES138 | D5: Bolsa Amarilla Impresa Milanesa x 1.800 gramos x 15 Unidades. Canal Intitucional. Bolsa Plana Pet//PEDB 70 micras | E5: 577 | F5: 577 | G5: =((F5/E5)*100)-100 -> 0
B6: BOLSAS LAMINADAS | C6: MPES143 | D6: Bolsa Impresa Roja Hamburguesa x 450 gramos x 5 unidades. Canal Moderno. Bolsa Flex Up Pet//PEBD 80 micras | E6: 437 | F6: 437 | G6: =((F6/E6)*100)-100 -> 0
B7: BOLSAS REGULARES | C7: MPES513 | D7: Bolsa AD BCO Impresa FAIZAN 23x25 + 4 cm en 1.0 ML | E7: 58 | F7: 58 | G7: =((F7/E7)*100)-100 -> 0
B8: CLIPS | C8: MPEP405 | D8: Grapas Poly-Clip GMBH 15-08 5 x 1,5 Carrete x 5,500 unidades | E8: 28 | F8: 27 | G8: =((F8/E8)*100)-100 -> -3.5714286
B9: CLIPS | C9: MPEP969 | D9: Clips HC25-3218T. Carrete x 2,400 unidades. | E9: 28 | F9: 52 | G9: =((F9/E9)*100)-100 -> 85.714286
B10: COLLARINES | C10: MPES155 | D10: Etiqueta Megasalchicha x 560 gramos x 6 unidades | E10: 115 | F10: 115 | G10: =((F10/E10)*100)-100 -> 0
B11: CORRUGADOS | C11: MPES959 | D11: Caja Hamburguesa x 2.700 gramos | E11: 1022 | F11: 1022 | G11: =((F11/E11)*100)-100 -> 0
B12: CORRUGADOS | C12: MPES968 | D12: Caja Koba Salchichón de Pollo Brakel x 500 gramos (15 unidades) | E12: 1624 | F12: 1624 | G12: =((F12/E12)*100)-100 -> 0
B13: CORRUGADOS | C13: MPES969 | D13: Caja Koba Jamón de Cerdo Viandé x 300 gramos (32 unidades) | E13: 1624 | F13: 1624 | G13: =((F13/E13)*100)-100 -> 0
B14: CORRUGADOS | C14: MPES972 | D14: Caja Koba Salchichón Tradicional Viandé x 500 gramos (15 unidades) | E14: 1624 | F14: 1624 | G14: =((F14/E14)*100)-100 -> 0
B15: CORRUGADOS | C15: MPES973 | D15: Caja Koba Super Combo Tradicional Viandé (9 unidades) | E15: 1727 | F15: 1727 | G15: =((F15/E15)*100)-100 -> 0
B16: CORRUGADOS | C16: MPES974 | D16: Caja Koba Salchicha Tradicional Viandé x 450 gramos. (22 unidades) | E16: 1816 | F16: 1816 | G16: =((F16/E16)*100)-100 -> 0
... B71: PELÍCULA SUPERIOR | C71: MPES461 | D71: Lámina Impresa Salchichón Cervecero Tajado x 50 gramos x 1,000 metros x 302 mm . | E71: 954 | F71: 954 | G71: =((F71/E71)*100)-100 -> 0

Sheet EXPLOSION ME DIC 2022
A1: Etiquetas de fila | B1: NECESIDAD DIC /2022 | C1: OCT - COP / UMB | D1: INVERSIÓN ME | E1: INVENTARIO NOV 30
A2: Lámina Inferior Sudpack GVP 130-423 mm (5.0 mils). 1 Rollo x 350 metros | B2: 59942.199 | C2: 9901.35 | D2: =C2*B2 -> 5.9350869e+08
A3: Grapas Poly-Clip GMBH R-ID M 07-150 Carrete x 6,800 unidades | B3: 2326841.8 | C3: 224 | D3: =C3*B3 -> 5.2121256e+08
A4: Lámina Inferior Sudpack GVA 200 BT 323 MM (8.MILS) 1 Rollo x 300 metros | B4: 9692.648 | C4: 20291 | D4: =C4*B4 -> 1.9667352e+08
A5: Fibrosa FVP CLS 140 B5 4 H5 Natural Corrugado. (Viandé) | B5: 6582.51 | C5: 24870.52 | D5: =C5*B5 -> 1.6371045e+08
A6: Separador 15 cm x 15 cm Impreso Highpack | B6: 1084064.2 | C6: 114 | D6: =C6*B6 -> 1.2358332e+08
A7: Fibrosa FVP CLS 95 B3 4 H3 Natural Corrugada x 25 metros. | B7: 13268.7 | C7: 8542.28 | D7: =C7*B7 -> 1.1334495e+08
A8: Lámina Superior Impresa Super Combo Tradicional Viandé x 900 gramos x 9 unidades. Ancho = 45 cms. (Pet / coextrusión HBA 73 micras). | B8: 3815 | C8: 26300 | D8: =C8*B8 -> 100334500
A9: Tubular Salchichón Cervecero Viande x 225 Gramos. Cal 40 | B9: 154000 | C9: 491.73 | D9: =C9*B9 -> 75726420
A10: Funda Celulosa 18 x 100 (Cartón x 9.144 metros x 300 tubos,C/tubo x 30.48 metros. 6 caddy x 50 tubos) | B10: 110144.6 | C10: 624.51 | D10: =C10*B10 -> 68786403
A11: Funda Celulosa 20 x 100 CE FP CLR | B11: 308000 | C11: 216.66 | D11: =C11*B11 -> 66731280
A12: Caja Koba Super Combo Tradicional Viandé (9 unidades) | B12: 38500 | C12: 1727 | D12: =C12*B12 -> 66489500
A13: Funda Colageno NDX 26/60 (cartón x 4,718 metros x 258 tubos, C/tubo x 18.29 metros. 6 Caddy x 43 tubos C/U) | B13: 25153.653 | C13: 1873.83 | D13: =C13*B13 -> 47133670
... A68: Etiqueta Salchicha Desayuno Premium x 125 Gramos x 5 Unidades | B68: 888.32 | C68: 65 | D68: =C68*B68 -> 57740.8
A70: Total general | B70: 5062049.9 | C70: 184708.59 | D70: =SUM(D2:D68) -> 2.6806775e+09

Sheet D1
A1: TABLA DE REFERENCIAS
A2: Marca | B2: Línea de PICADOS SALCHICHAS | C2: ='CIF Y PV'!F6 -> MB-JUN
A3: D1 | B3: SALCHICHA PERRO CALIENTE VIANDE X 240 G X 6 UND | C3: =VLOOKUP(B3,'MB FEB'!B3:D86,3,FALSE) -> 0.38889371
A4: D1 | B4: SALCHICHA SUPER PERRO VIANDE X 400 G X 5 UND | C4: =VLOOKUP(B4,'MB FEB'!B4:D87,3,FALSE) -> 0.39099101
B5: LINEA SALCHICHAS | C5: =AVERAGE(C3:C4) -> 0.38994236
A6: Marca | B6: Línea de PICADOS CHORIZOS | C6: ='CIF Y PV'!F6 -> MB-JUN
A7: D1 | B7: CHORIZO ANTIOQUEÑO X 225 VIANDE | C7: =VLOOKUP(B7,'MB FEB'!B7:D90,3,FALSE) -> 0.35182806
A8: D1 | B8: CHORIZO CON TERNERA VIANDE X 225 GRS 5 UND | C8: =VLOOKUP(B8,'MB FEB'!B8:D91,3,FALSE) -> 0.32120562
A9: D1 | B9: CHORIZO SANTARROSANO VIANDE X 225 GRS 5 UNDS | C9: ='MB FEB'!D41 -> 0.31001682
B10: LINEA CHORIZOS | C10: =AVERAGE(C7:C8) -> 0.33651684
A11: Marca | B11: Línea de SALCHICHONES | C11: ='CIF Y PV'!F6 -> MB-JUN
A12: D1 | B12: SCHON. TRADICIONAL VIANDE X 500 G | C12: =VLOOKUP(B12,'MB FEB'!B11:D94,3,FALSE) -> 0.39602175
A13: D1 | B13: SCHON. POLLO BRAKEL X 500 G | C13: =VLOOKUP(B13,'MB FEB'!B12:D95,3,FALSE) -> 0.39872019
A14: D1 | B14: SNACK CERVECERITO X150 GRS | C14: ='MB FEB'!D51 -> 0.29202328
B15: LINEA SALCHICHICHONES | C15: =AVERAGE(C12:C13) -> 0.39737097
A16: Marca | B16: Línea de BARRAS | C16: ='CIF Y PV'!F6 -> MB-JUN
A17: D1 | B17: JAMON PREMIUM VIANDE X 300 G X 15 UND | C17: =VLOOKUP(B17,'MB FEB'!B14:D98,3,FALSE) -> 0.36652172
A18: D1 | B18: MORTADELA JAMONADA VIANDE X 400 GRS | C18: ='MB FEB'!D55 -> 0.29387153
B19: LINEA JAMONES | C19: =AVERAGE(C17) -> 0.36652172
A20: Marca | B20: Línea OFERTAS | C20: ='CIF Y PV'!F6 -> MB-JUN
A21: D1 | B21: SUPER COMBO VIANDE * 900 | C21: =VLOOKUP(B21,'MB FEB'!B16:D101,3,FALSE) -> 0.33424604
B22: LINEA OFERTAS | C22: =AVERAGE(C21) -> 0.33424604
A23: Marca | B23: Línea TOCINOS | C23: ='CIF Y PV'!F6 -> MB-JUN
B26: LINEA | C26: ='CIF Y PV'!F6 -> MB-JUN | D26: META
B27: LINEA SALCHICHAS | C27: =VLOOKUP(B27,B3:C22,2,FALSE) -> 0.38994236 | D27: 0.25
B28: LINEA CHORIZOS | C28: =VLOOKUP(B28,B4:C23,2,FALSE) -> 0.33651684 | D28: 0.25
B29: LINEA SALCHICHICHONES | C29: =VLOOKUP(B29,B5:C24,2,FALSE) -> 0.39737097 | D29: 0.25
B30: LINEA JAMONES | C30: =VLOOKUP(B30,B6:C25,2,FALSE) -> 0.36652172 | D30: 0.25
B31: LINEA OFERTAS | C31: =VLOOKUP(B31,B7:C26,2,FALSE) -> 0.33424604 | D31: 0.25

Sheet FAZAN
A1: TABLA DE REFERENCIAS
A2: Marca | B2: Línea de PICADOS SALCHICHAS | C2: ='CIF Y PV'!F6 -> MB-JUN
A3: Fazàn | B3: SCHA. CLASICA X 225 G X 9 UND | C3: =VLOOKUP(B3,'MB FEB'!B3:D85,3,FALSE) -> 0.60707026
A4: Fazàn | B4: SALCHICHA CLASICA X 450 G - 18 UND | C4: =VLOOKUP(B4,'MB FEB'!B4:D86,3,FALSE) -> 0.55693962
A5: Fazàn | B5: SALCHICHA PERRO CALIENTE X 480 G - 12 UND | C5: =VLOOKUP(B5,'MB FEB'!B5:D87,3,FALSE) -> 0.62997797
A6: Fazàn | B6: SALCHICHA SUPER PERRO X 500 G | C6: =VLOOKUP(B6,'MB FEB'!B6:D88,3,FALSE) -> 0.52052742
A7: Fazàn | B7: SALCHICHA MINIPERRO X 1.000 G - 40 UND | C7: =VLOOKUP(B7,'MB FEB'!B7:D89,3,FALSE) -> 0.50082322
A8: Fazàn | B8: SALCHICHA SUPER PERRO X 2.500 G - 50 UND | C8: =VLOOKUP(B8,'MB FEB'!B8:D90,3,FALSE) -> 0.46486749
A9: Fazàn | B9: SCHA. DESAYUNO PREMIUM X 115 G X 5 UND | C9: =VLOOKUP(B9,'MB FEB'!B9:D91,3,FALSE) -> 0.53683079
A10: Fazàn | B10: SALCHICHA DESAYUNO PREMIUM X 480 G - 14 UND | C10: =VLOOKUP(B10,'MB FEB'!B10:D92,3,FALSE) -> 0.50502403
A11: Fazàn | B11: SALCHICHA DESAYUNO PREMIUM FZAN X 240 X 7UND | C11: =VLOOKUP(B11,'MB FEB'!B11:D93,3,FALSE) -> 0.53664543
A12: Fazàn | B12: SALCHICHA DESAYUNO PREMIUM X 960 | C12: =VLOOKUP(B12,'MB FEB'!B13:D95,3,FALSE) -> 0.50195425
A13: Fazàn | B13: SCHA JUMBO X 1200 G | C13: =VLOOKUP(B13,'MB FEB'!B14:D96,3,FALSE) -> 0.44979161
A14: Fazàn | B14: SCHA JUMBO X 450 G FAZÁN | C14: =VLOOKUP(B14,'MB FEB'!B15:D98,3,FALSE) -> 0.52236802
A15: Fazàn | B15: SALCHICHA MANGUERA X 560 G - 6 UND | C15: =VLOOKUP(B15,'MB FEB'!B16:D99,3,FALSE) -> 0.49362857
A16: Fazàn | B16: MEGA SALCHICHA TIPO MANGUERA 1120 G 12 UND | C16: =VLOOKUP(B16,'MB FEB'!B16:D100,3,FALSE) -> 0.45830782
A17: Fazàn | B17: SALCHICHA LONG X 1100 GRS X 20 UNDS | C17: =VLOOKUP(B17,'MB FEB'!B17:D101,3,FALSE) -> 0.38767084
A18: Fazàn | B18: SALCHICHA UNINORTE X 1280 GRS X 16 UNDS | C18: =VLOOKUP(B18,'MB FEB'!B18:D102,3,FALSE) -> 0.49236164
A19: Fazàn | B19: ='MB FEB'!B23 -> SALCHICHA SUIZA X 990 GRS 9 UNDS | C19: ='MB FEB'!D23 -> 0.41897254
B20: LINEA SALCHICHAS | C20: =AVERAGE(C3:C18) -> 0.51029931
A21: Marca | B21: Línea de PICADOS CHORIZOS | C21: ='CIF Y PV'!F6 -> MB-JUN
A22: Fazàn | B22: CHORIZO DE CERDO X 250 G - 5 UND - Fazán | C22: =VLOOKUP(B22,'MB FEB'!B24:D107,3,FALSE) -> 0.5046436
A23: Fazàn | B23: CHORIZO DE CERDO X 400 G - 8 UND | C23: =VLOOKUP(B23,'MB FEB'!B25:D108,3,FALSE) -> 0.47834783
A24: Fazàn | B24: CHORIZO DE CERDO X 1000 G - 20 UND | C24: =VLOOKUP(B24,'MB FEB'!B25:D109,3,FALSE) -> 0.44865358
A25: Fazàn | B25: CHORIZO CON TERNERA X 110 G - 2 UND | C25: =VLOOKUP(B25,'MB FEB'!B25:D110,3,FALSE) -> 0.41924188
A26: Fazàn | B26: CHORIZO CON TERNERA X 220 G - 4 UND | C26: =VLOOKUP(B26,'MB FEB'!B26:D111,3,FALSE) -> 0.41018414
A27: Fazàn | B27: CHORIZO CON TERNERA X 440 G - 8 UND FZAN | C27: =VLOOKUP(B27,'MB FEB'!B27:D112,3,FALSE) -> 0.44823859
A28: Fazàn | B28: CHORIZO CON TERNERA X 1100 G - | C28: =VLOOKUP(B28,'MB FEB'!B29:D114,3,FALSE) -> 0.4410006
A29: Fazàn | B29: CHORIZO SANTARROSANO x 300 | C29: =VLOOKUP(B29,'MB FEB'!B30:D115,3,FALSE) -> 0.55181118
A30: Fazàn | B30: CHORIZO SANTARROSANO x 480 | C30: =VLOOKUP(B30,'MB FEB'!B31:D116,3,FALSE) -> 0.55072142
A31: Fazàn | B31: CHORIZO SANTARROSANO x 1200 | C31: =VLOOKUP(B31,'MB FEB'!B31:D117,3,FALSE) -> 0.50712913
A32: Fazàn | B32: CHORIZO COCTEL SANTARROSANO X 300 xx UND | C32: =VLOOKUP(B32,'MB FEB'!B32:D118,3,FALSE) -> 0.47635479
A33: Fazàn | B33: CHORIZO COCTEL SANTARROSANO X 1000 74 UND | C33: =VLOOKUP(B33,'MB FEB'!B33:D119,3,FALSE) -> 0.44850789
A34: Fazàn | B34: CHORIZO SANTARROSANO LARGO PERRITOS 1.2 G 15 UND | C34: =VLOOKUP(B34,'MB FEB'!B34:D120,3,FALSE) -> 0.44358077
B35: LINEA CHORIZOS | C35: =AVERAGE(C22:C34) -> 0.47141657
A36: Marca | B36: Línea de SALCHICHONES | C36: ='CIF Y PV'!F6 -> MB-JUN
A37: Fazàn | B37: SALCHICHON AUTENTICO X 750 G | C37: =VLOOKUP(B37,'MB FEB'!B37:D123,3,FALSE) -> 0.56055922
A38: Fazàn | B38: SALCHICHON CERVECERO X 500 G | C38: =VLOOKUP(B38,'MB FEB'!B39:D124,3,FALSE) -> 0.62036304
A39: Fazàn | B39: SALCHICHON CERVECERO X 750 G | C39: =VLOOKUP(B39,'MB FEB'!B39:D125,3,FALSE) -> 0.58120586
A40: Fazàn | B40: SALCHICHON CERVECERO X 1.300 G | C40: =VLOOKUP(B40,'MB FEB'!B40:D126,3,FALSE) -> 0.54643466
...

Sheet MB FEB
A1: TABLA DE REFERENCIAS
A2: Marca | B2: Línea de PICADOS SALCHICHAS | C2: MB - JUNIO COSTOS | D2: MB - JUNIO | E2: MB - MAY | F2: %
A3: Fazàn | B3: SCHA. CLASICA X 225 G X 9 UND | D3: ='SCHA CLÁSICA 225 G 9 UND'!H49 -> 0.60707026 | E3: 0.59656243 | F3: =((E3/D3)*100-100) -> -1.7309087
A4: Fazàn | F4: =((E4/D4)*100-100) -> #DIV/0!
A5: Fazàn | B5: SALCHICHA CLASICA X 450 G - 18 UND | D5: ='SCHA CLÁSICA 450 G 18 UND'!H49 -> 0.55693962 | E5: 0.54567661 | F5: =((E5/D5)*100-100) -> -2.0223043
A6: Fazàn | B6: SCHA. SELECCIONADA VIANDE X 450 G X 16 UND | F6: =((E6/D6)*100-100) -> #DIV/0!
A7: Fazàn | B7: SALCHICHA PERRO CALIENTE X 480 G - 12 UND | D7: ='SCHA PERRO X 480 G - 12 UNDS'!H50 -> 0.62997797 | E7: 0.61103573 | F7: =((E7/D7)*100-100) -> -3.0068112
A8: Fazàn | B8: SALCHICHA SUPER PERRO X 500 G | D8: ='SCHA S. PERRO X 500 '!H49 -> 0.52052742 | E8: 0.51160819 | F8: =((E8/D8)*100-100) -> -1.7134986
A9: Fazàn | B9: SALCHICHA MINIPERRO X 1.000 G - 40 UND | D9: ='MINI PERRO X 1.0'!H49 -> 0.50082322 | E9: 0.48386113 | F9: =((E9/D9)*100-100) -> -3.3868408
A10: Fazàn | B10: SALCHICHA SUPER PERRO X 2.500 G - 50 UND | D10: ='SUPER PERRO X 2500 RX'!H49 -> 0.46486749 | E10: 0.44837769 | F10: =((E10/D10)*100-100) -> -3.5472037
A11: Fazàn | B11: SCHA. DESAYUNO PREMIUM X 115 G X 5 UND | D11: ='SCHA DESAYUNO 115 G - 5 UNDS'!H50 -> 0.53683079 | E11: 0.54670193 | F11: =((E11/D11)*100-100) -> 1.8387813
A12: Fazàn | B12: SALCHICHA DESAYUNO PREMIUM X 480 G - 14 UND | D12: ='SCHA DESAYUNO 480 G -14 UND'!H50 -> 0.50502403 | E12: 0.47995401 | F12: =((E12/D12)*100-100) -> -4.9641233
A13: Fazàn | B13: SALCHICHA DESAYUNO PREMIUM FZAN X 240 X 7UND | D13: ='SCHA DESAYUNO FZA x 240 x 7 UND'!H50 -> 0.53664543 | E13: 0.5139396 | F13: =((E13/D13)*100-100) -> -4.2310675
A14: Fazàn | B14: SALCHICHA DESAYUNO PREMIUM X 960 | D14: ='SCHA DESAYUNO 960 G'!H49 -> 0.50195425 | E14: 0.47529336 | F14: =((E14/D14)*100-100) -> -5.3114189
A15: Fazàn | B15: SCHA JUMBO X 1200 G | D15: ='SCHA JUMBO X 1200 G'!G50 -> 0.44979161 | E15: 0.43315422 | F15: =((E15/D15)*100-100) -> -3.6989108
A16: Fazàn | B16: SCHA JUMBO X 450 G FAZÁN | D16: ='SCHA JUMBO X 450G fazán'!G51 -> 0.52236802 | E16: 0.50862991 | F16: =((E16/D16)*100-100) -> -2.6299662
A17: Fazàn | B17: SALCHICHA MANGUERA X 560 G - 6 UND | D17: ='SCHA MANGUERA 560 G - 6 UND'!H46 -> 0.49362857 | E17: 0.48863147 | F17: =((E17/D17)*100-100) -> -1.0123198
A18: Viande | B18: MEGA SALCHICHA TIPO MANGUERA 1120 G 12 UND | D18: ='SCHA MANGUERA 1120G - 12UND'!H47 -> 0.45830782 | E18: 0.4507582 | F18: =((E18/D18)*100-100) -> -1.64728
A19: Viande | B19: SALCHICHA PERRO CALIENTE VIANDE X 240 G X 6 UND | D19: ='PERRO CALIENTE VIANDE x 240G'!H55 -> 0.38889371 | E19: 0.36799175 | F19: =((E19/D19)*100-100) -> -5.3747206
A20: Viande | B20: SALCHICHA SUPER PERRO VIANDE X 400 G X 5 UND | D20: ='SUPER PERRO VIANDE X 400G RX'!H54 -> 0.39099101 | E20: 0.39302729 | F20: =((E20/D20)*100-100) -> 0.52080125
A21: Fazàn | B21: SALCHICHA LONG X 1100 GRS X 20 UNDS | D21: ='SALCHICHA LONG'!H54 -> 0.38767084 | E21: 0.36394502 | F21: =((E21/D21)*100-100) -> -6.1200941
A22: Fazàn | B22: SALCHICHA UNINORTE X 1280 GRS X 16 UNDS | D22: ='SALCHICHA UNINORTE'!H54 -> 0.49236164 | E22: 0.47146796 | F22: =((E22/D22)*100-100) -> -4.2435642
A23: Fazàn | B23: SALCHICHA SUIZA X 990 GRS 9 UNDS | D23: {='SCHA SUIZA X 9'!D50:F50} -> 0.41897254 | E23: 0 | F23: 0
A24: Marca | B24: Línea de PICADOS CHORIZOS | C24: MB - JUNIO COSTOS | D24: MB - JUNIO | E24: MB - MAY | F24: %
A25: Faizán | B25: CHORIZO DE CERDO X 250 G - 5 UND - Fazán | D25: ='CHORIZO DE CERDO 250 FAZÁN'!H46 -> 0.5046436 | E25: 0.48774426 | F25: =((E25/D25)*100)-100 -> -3.3487677
A26: Faizán | B26: CHORIZO DE CERDO X 400 G - 8 UND | D26: ='CHORIZO DE CERDO 400 g'!H46 -> 0.47834783 | E26: 0.45729626 | F26: =((E26/D26)*100)-100 -> -4.4008926
A27: Faizán | B27: CHORIZO DE CERDO X 1000 G - 20 UND | D27: ='CHORIZO DE CERDO 1000'!H44 -> 0.44865358 | E27: 0.42854515 | F27: =((E27/D27)*100)-100 -> -4.4819496
A28: Faizán | B28: CHORIZO CON TERNERA X 110 G - 2 UND | D28: ='CHRZ CON TERNERA 110 G 2 UND'!H44 -> 0.41924188 | E28: 0.41005234 | F28: =((E28/D28)*100)-100 -> -2.1919419
A29: Faizán | B29: CHORIZO CON TERNERA X 220 G - 4 UND | D29: ='CHORIZO CON TERNERA 220'!H44 -> 0.41018414 | E29: 0.39403717 | F29: =((E29/D29)*100)-100 -> -3.9365176
A30: Faizán | B30: CHORIZO CON TERNERA X 440 G - 8 UND FZAN | D30: ='CHORIZO CON TERNERA 440 G FZAN'!H45 -> 0.44823859 | E30: 0.4462477 | F30: =((E30/D30)*100)-100 -> -0.44415966
A31: Faizán | B31: CHORIZO CON TERNERA X 1100 G - | D31: ='CHORIZO CON TERNERA 1100'!H43 -> 0.4410006 | E31: 0.42971815 | F31: =((E31/D31)*100)-100 -> -2.5583746
A32: Faizán | B32: CHORIZO SANTARROSANO x 300 | D32: ='CHORIZO SANTARROSANO x 300'!I46 -> 0.55181118 | E32: 0.55049237 | F32: =((E32/D32)*100)-100 -> -0.23899596
A33: Faizán | B33: CHORIZO SANTARROSANO x 480 | D33: ='CHORIZO SANTARROSANO x 480 '!I46 -> 0.55072142 | E33: 0.54971082 | F33: =((E33/D33)*100)-100 -> -0.18350325
A34: Faizán | B34: CHORIZO SANTARROSANO x 1200 | D34: ='CHORIZO SANTARROSANO x 1200'!I46 -> 0.50712913 | E34: 0.5052663 | F34: =((E34/D34)*100)-100 -> -0.36732838
A35: Faizán | B35: CHORIZO COCTEL SANTARROSANO X 300 xx UND | D35: ='CHORIZO SANTA COCTEL x 300'!I47 -> 0.47635479 | E35: 0.47019606 | F35: =((E35/D35)*100)-100 -> -1.2928865
A36: Faizán | B36: CHORIZO COCTEL SANTARROSANO X 1000 74 UND | D36: ='CHORIZO SANTA COCTEL x 1000'!I46 -> 0.44850789 | E36: 0.44317735 | F36: =((E36/D36)*100)-100 -> -1.1885037
A37: Faizán | B37: CHORIZO SANTARROSANO LARGO PERRITOS 1.2 G 15 UND | D37: ='CHORIZO SANTA LARGO x 1200 '!I46 -> 0.44358077 | E37: 0.44346944 | F37: =((E37/D37)*100)-100 -> -0.025097701
A38: FAZÀN | B38: CHORIZO RED DE ALIMENTOS
A39: Viande | B39: CHORIZO ANTIOQUEÑO X 225 VIANDE | D39: ='CHORIZO ANTIOQUEÑO VIANDE'!H52 -> 0.35182806 | E39: 0.3092663 | F39: =((E39/D39)*100)-100 -> -12.097319
A40: Viande | B40: CHORIZO CON TERNERA VIANDE X 225 GRS 5 UND | D40: ='CHORIZO TERNERA VIANDE'!H54 -> 0.32120562 | E40: 0.27949049 | F40: =((E40/D40)*100)-100 -> -12.987047
...

Sheet CERVECERO 500
B2: CERVECERO FAIZAN X 500 G
K3: 1 Und | L3: Q Batch
B4: CÓDIGO | C4: DESCRIPCIÓN | D4: CATIDAD | E4: % | F4: =+'CIF Y PV'!$F$2 -> JUN-COP/Kg | G4: =+'CIF Y PV'!$G$2 -> JUN-COP/APP | H4: =+'CIF Y PV'!$H$2 -> MAY-COP/Kg | I4: =+'CIF Y PV'!$I$2 -> MAY-COP/APP | J4: % | K4: =+D22/1000 -> 0.5145 | L4: 2011.05
B5: =VLOOKUP(C5,[1]Hoja1!$B$2:$C$260,2,FALSE) -> 1112001 | C5: PASTA DE POLLO IMPORTADA PREMIUM | D5: 0.18012645 | E5: 35.01 | F5: =VLOOKUP(B5,[2]Hoja1!$C$2:$E$279,3,FALSE) -> 3663.96 | G5: =D5*F5 -> 659.97611 | H5: 4222.72 | I5: =H5*D5 -> 760.62356 | J5: =((F5/H5)*100)-100 -> -13.232229 | K5: =$K$4*E5% -> 0.18012645 | L5: =$L$4*E5 -> 70406.86 | M5: =L5*F5 -> 2.5796792e+08
B6: =VLOOKUP(C6,[1]Hoja1!$B$2:$C$260,2,FALSE) -> 1121009 | C6: TOCINO NACIONAL | D6: 0.0225351 | E6: 4.38 | F6: =VLOOKUP(B6,[2]Hoja1!$C$2:$E$279,3,FALSE) -> 8741.62 | G6: =D6*F6 -> 196.99328 | I6: =H6*D6 -> 0 | K6: =$K$4*E6% -> 0.0225351 | L6: =$L$4*E6 -> 8808.399 | M6: =L6*F6 -> 76999677
B7: =VLOOKUP(C7,[1]Hoja1!$B$2:$C$260,2,FALSE) -> 1122007 | C7: RECORTE DE CERDO 80/20 IMPORTADO | D7: 0.04121145 | E7: 8.01 | F7: =VLOOKUP(B7,[2]Hoja1!$C$2:$E$279,3,FALSE) -> 11229.33 | G7: =D7*F7 -> 462.77697 | I7: =H7*D7 -> 0 | K7: =$K$4*E7% -> 0.04121145 | L7: =$L$4*E7 -> 16108.51 | M7: =L7*F7 -> 1.8088778e+08
B8: =VLOOKUP(C8,[1]Hoja1!$B$2:$C$260,2,FALSE) -> 2906001 | C8: EMULSION DE PIEL DE CERDO | D8: 0.0488775 | E8: 9.5 | F8: =VLOOKUP(B8,[2]Hoja1!$C$2:$E$279,3,FALSE) -> 1956.71 | G8: =D8*F8 -> 95.639093 | H8: 2033.73 | I8: =H8*D8 -> 99.403638 | J8: =((F8/H8)*100)-100 -> -3.7871301 | K8: =$K$4*E8% -> 0.0488775 | L8: =$L$4*E8 -> 19104.975 | M8: =L8*F8 -> 37382896
B9: =VLOOKUP(C9,[1]Hoja1!$B$2:$C$260,2,FALSE) -> 1131002 | C9: AGUA POTABLE | D9: 0.1402527 | E9: 27.26 | F9: =VLOOKUP(B9,[2]Hoja1!$C$2:$E$279,3,FALSE) -> 0 | G9: =D9*F9 -> 0 | H9: 0 | I9: =H9*D9 -> 0 | K9: =$K$4*E9% -> 0.1402527 | L9: =$L$4*E9 -> 54821.223 | M9: =L9*F9 -> 0
B10: 1210005 | C10: SAL YODADA REFISAL | D10: 0.004116 | E10: 0.8 | F10: =VLOOKUP(B10,[2]Hoja1!$C$2:$E$279,3,FALSE) -> 1356 | G10: =D10*F10 -> 5.581296 | K10: =$K$4*E10% -> 0.004116 | L10: =$L$4*E10 -> 1608.84
B11: 1210010 | C11: CLORURO DE POTASIO - KCL | D11: 0.00272685 | E11: 0.53 | F11: =VLOOKUP(B11,[2]Hoja1!$C$2:$E$279,3,FALSE) -> 11600 | G11: =D11*F11 -> 31.63146 | H11: 8910.1 | I11: =H11*D11 -> 24.296506 | J11: =((F11/H11)*100)-100 -> 30.189336 | K11: =$K$4*E11% -> 0.00272685 | L11: =$L$4*E11 -> 1065.8565 | M11: =L11*F11 -> 12363935
B12: =VLOOKUP(C12,[1]Hoja1!$B$2:$C$260,2,FALSE) -> 1210004 | C12: SAL CURANTE AL 12 % | D12: 0.0008232 | E12: 0.16 | F12: =VLOOKUP(B12,[2]Hoja1!$C$2:$E$279,3,FALSE) -> 3841 | G12: =D12*F12 -> 3.1619112 | H12: 3508.01 | I12: =H12*D12 -> 2.8877938 | J12: =((F12/H12)*100)-100 -> 9.4922762 | K12: =$K$4*E12% -> 0.0008232 | L12: =$L$4*E12 -> 321.768 | M12: =L12*F12 -> 1235910.9
B13: =VLOOKUP(C13,[1]Hoja1!$B$2:$C$260,2,FALSE) -> 121007 | C13: SUPRA MEAT F451 | D13: 0.0002558365 | E13: 12 | F13: =VLOOKUP(B13,[2]Hoja1!$C$2:$E$279,3,FALSE) -> 16905 | G13: =D13*F13 -> 4.3249161 | H13: 16100 | I13: =H13*D13 -> 4.1189677 | J13: =((F13/H13)*100)-100 -> 5 | K13: =$K$4*E13% -> 0.06174 | L13: =$L$4*E13 -> 24132.6 | M13: =L13*F13 -> 407961603
B14: =VLOOKUP(C14,[1]Hoja1!$B$2:$C$260,2,FALSE) -> 1230003 | C14: PREPARADO SABOR CERVECERO NEO | D14: 0.0071941225 | E14: 1.3982745 | F14: =VLOOKUP(B14,[2]Hoja1!$C$2:$E$279,3,FALSE) -> 20099.99 | G14: =D14*F14 -> 144.60179 | H14: 19145.99 | I14: =H14*D14 -> 137.7386 | J14: =((F14/H14)*100)-100 -> 4.9827666 | K14: =$K$4*E14% -> 0.0071941225 | L14: =$L$4*E14 -> 2812 | M14: =L14*F14 -> 56521172
B15: =VLOOKUP(C15,[1]Hoja1!$B$2:$C$260,2,FALSE) -> 1220009 | C15: CEBOLLA EN POLVO | D15: 0.0002558365 | E15: 0.049725268 | F15: =VLOOKUP(B15,[2]Hoja1!$C$2:$E$279,3,FALSE) -> 21312.16 | G15: =D15*F15 -> 5.4524285 | H15: 20299 | I15: =H15*D15 -> 5.1932252 | J15: =((F15/H15)*100)-100 -> 4.9911818 | K15: =$K$4*E15% -> 0.0002558365 | L15: =$L$4*E15 -> 100 | M15: =L15*F15 -> 2131216
B16: =VLOOKUP(C16,[1]Hoja1!$B$2:$C$260,2,FALSE) -> 1220005 | C16: AJO MOLIDO DESHIDRATADO B.1 | D16: 0.0002558365 | E16: 0.049725268 | F16: =VLOOKUP(B16,[2]Hoja1!$C$2:$E$279,3,FALSE) -> 17429.99 | G16: =D16*F16 -> 4.4592277 | H16: 17430 | I16: =H16*D16 -> 4.4592303 | J16: =((F16/H16)*100)-100 -> -5.7372347e-05 | K16: =$K$4*E16% -> 0.0002558365 | L16: =$L$4*E16 -> 100 | M16: =L16*F16 -> 1742999
B17: =VLOOKUP(C17,[1]Hoja1!$B$2:$C$260,2,FALSE) -> 1260009 | C17: PROTEINA CONCENTRADA DE SOYA 70% | D17: 0.02046692 | E17: 3.9780214 | F17: =VLOOKUP(B17,[2]Hoja1!$C$2:$E$279,3,FALSE) -> 7033.69 | G17: =D17*F17 -> 143.95797 | H17: 9565.21 | I17: =H17*D17 -> 195.77039 | J17: =((F17/H17)*100)-100 -> -26.465911 | K17: =$K$4*E17% -> 0.02046692 | L17: =$L$4*E17 -> 8000 | M17: =L17*F17 -> 56269520
B18: =VLOOKUP(C18,[1]Hoja1!$B$2:$C$260,2,FALSE) -> 1260011 | C18: ALMIDON DE PAPA | D18: 0.04501875 | E18: 8.75 | F18: =VLOOKUP(B18,[2]Hoja1!$C$2:$E$279,3,FALSE) -> 4450.01 | G18: =D18*F18 -> 200.33389 | H18: 4500 | I18: =H18*D18 -> 202.58437 | J18: =((F18/H18)*100)-100 -> -1.1108889 | K18: =$K$4*E18% -> 0.04501875 | L18: =$L$4*E18 -> 17596.688 | M18: =L18*F18 -> 78305435
B19: =VLOOKUP(C19,[1]Hoja1!$B$2:$C$260,2,FALSE) -> 1270009 | C19: HUMO TRUSMOKE DRY x 20 KG | D19: 0.00048608936 | E19: 0.094478009 | F19: =VLOOKUP(B19,[2]Hoja1!$C$2:$E$279,3,FALSE) -> 57046.53 | G19: =D19*F19 -> 27.729711 | H19: 53849.37 | I19: =H19*D19 -> 26.175606 | J19: =((F19/H19)*100)-100 -> 5.9372282 | K19: =$K$4*E19% -> 0.00048608936 | L19: =$L$4*E19 -> 190 | M19: =L19*F19 -> 10838841
B20: TOTAL | D20: =SUM(D5:D19) -> 0.51460264 | E20: =SUM(E5:E19) -> 111.97022 | G20: =SUM(G5:G19) -> 1986.6201 | I20: =SUM(I5:I19) -> 1463.2519 | J20: =((G20/I20)*100)-100 -> 35.767469 | K20: =SUM(K5:K19) -> 0.57608681 | M20: =SUM(M5:M19) -> 1.1806089e+09
B22: MERMAS | D22: =+C25+(C25*C31%) -> 514.5
B23: Linea | C23: Salchichones
B24: Referencia | C24: Salchichón Cervecero Faizán
B25: Presentación en Gramos | C25: 500
B26: Máquina | C26: 0
B27: Cocción | C27: 0.2
B28: Frío | C28: 0.2
B29: Recorte | C29: 0.5
B30: Sobrepeso | C30: 2
B31: Merma Total | C31: =C30+C29+C28+C27 -> 2.9
B33: MATERIAL DE EMPAQUE
B34: CÓDIGO | C34: DESCRIPCIÓN | D34: CATIDAD | E34: =+'CIF Y PV'!$F$4 -> JUN-COP/UMB | F34: =+'CIF Y PV'!$G$4 -> JUN-COP/APP | G34: =+'CIF Y PV'!$H$4 -> MAY-COP/UMB | H34: =+'CIF Y PV'!$I$4 -> MAY-COP/APP | I34: % | J34: 30270
B35: 1380005 | C35: GRAPAS POLY- R-ID M 07-150 | D35: 2 | E35: =VLOOKUP(B35,[2]Hoja1!$C$2:$E$279,3,FALSE) -> 29.02 | F35: =E35*D35 -> 58.04 | G35: 31.68 | H35: =G35*D35 -> 63.36 | I35: =((E35/G35)*100)-100 -> -8.3964646 | J35: =J34*D35 -> 60540
B36: 1370016 | C36: TUBU SALCHICHON CERVECERO FAIZAN X 500G | D36: 0.28 | E36: =VLOOKUP(B36,[2]Hoja1!$C$2:$E$279,3,FALSE) -> 627.22 | F36: =E36*D36 -> 175.6216 | G36: 668.96 | H36: =G36*D36 -> 187.3088 | I36: =((E36/G36)*100)-100 -> -6.239536 | J36: =J34*D36 -> 8475.6
C37: TOTAL | F37: =SUM(F35:F36) -> 233.6616 | H37: =SUM(H35:H36) -> 250.6688 | I37: =((F37/H37)*100)-100 -> -6.7847295
F38: =+'CIF Y PV'!$G$1 -> MAYO
B39: TOTAL INSUMOS (UND 500 G) | D39: =+F37+G20 -> 2220.2817
B40: ASIGNACIÓN MOD/CIF | D40: =+('CIF Y PV'!C3/1000)*500 -> 945
B41: TOTAL COSTO POR UND (500) | D41: =+D39+D40 -> 3165.2817
B42: PRECIO DE VENTA | D42: ='CIF Y PV'!C57 -> 8337.654
B43: MB | F43: =+(D42-D41)/D42 -> 0.62036304
...

Sheet CERVECERO 750
B2: CERVECERO FAIZAN X 750 G
K3: 1 UND | L3: 1 bacth
B4: CÓDIGO | C4: DESCRIPCIÓN | D4: CATIDAD | E4: % | F4: =+'CIF Y PV'!$F$2 -> JUN-COP/Kg | G4: =+'CIF Y PV'!$G$2 -> JUN-COP/APP | H4: =+'CIF Y PV'!$H$2 -> MAY-COP/Kg | I4: =+'CIF Y PV'!$I$2 -> MAY-COP/APP | J4: % | K4: =+D22/1000 -> 0.77175 | L4: 2011.05
B5: =VLOOKUP(C5,[1]Hoja1!$B$2:$C$260,2,FALSE) -> 1112001 | C5: PASTA DE POLLO IMPORTADA PREMIUM | D5: 0.27018968 | E5: 35.01 | F5: =VLOOKUP(B5,[2]Hoja1!$C$2:$E$279,3,FALSE) -> 3663.96 | G5: =D5*F5 -> 989.96416 | H5: 4222.72 | I5: =H5*D5 -> 1140.9353 | J5: =((F5/H5)*100)-100 -> -13.232229 | K5: =$K$4*E5% -> 0.27018968 | L5: =$L$4*E5 -> 70406.86
B6: =VLOOKUP(C6,[1]Hoja1!$B$2:$C$260,2,FALSE) -> 1121009 | C6: TOCINO NACIONAL | D6: 0.03380265 | E6: 4.38 | F6: =VLOOKUP(B6,[2]Hoja1!$C$2:$E$279,3,FALSE) -> 8741.62 | G6: =D6*F6 -> 295.48992 | H6: 2033.73 | I6: =H6*D6 -> 68.745463 | J6: =((F6/H6)*100)-100 -> 329.83189 | K6: =$K$4*E6% -> 0.03380265 | L6: =$L$4*E6 -> 8808.399
B7: =VLOOKUP(C7,[1]Hoja1!$B$2:$C$260,2,FALSE) -> 1122007 | C7: RECORTE DE CERDO 80/20 IMPORTADO | D7: 0.061817175 | E7: 8.01 | F7: =VLOOKUP(B7,[2]Hoja1!$C$2:$E$279,3,FALSE) -> 11229.33 | G7: =D7*F7 -> 694.16546 | H7: 0 | I7: =H7*D7 -> 0 | J7: =((F7/H7)*100)-100 -> #DIV/0! | K7: =$K$4*E7% -> 0.061817175 | L7: =$L$4*E7 -> 16108.51
B8: =VLOOKUP(C8,[1]Hoja1!$B$2:$C$260,2,FALSE) -> 2906001 | C8: EMULSION DE PIEL DE CERDO | D8: 0.07331625 | E8: 9.5 | F8: =VLOOKUP(B8,[2]Hoja1!$C$2:$E$279,3,FALSE) -> 1956.71 | G8: =D8*F8 -> 143.45864 | H8: 8910.1 | I8: =H8*D8 -> 653.25512 | J8: =((F8/H8)*100)-100 -> -78.039416 | K8: =$K$4*E8% -> 0.07331625 | L8: =$L$4*E8 -> 19104.975
B9: =VLOOKUP(C9,[1]Hoja1!$B$2:$C$260,2,FALSE) -> 1131002 | C9: AGUA POTABLE | D9: 0.21037905 | E9: 27.26 | F9: =VLOOKUP(B9,[2]Hoja1!$C$2:$E$279,3,FALSE) -> 0 | G9: =D9*F9 -> 0 | H9: 3508.01 | I9: =H9*D9 -> 738.01181 | J9: =((F9/H9)*100)-100 -> -100 | K9: =$K$4*E9% -> 0.21037905 | L9: =$L$4*E9 -> 54821.223
B10: 1210005 | C10: SAL YODADA REFISAL | D10: 0.006174 | E10: 0.8 | F10: =VLOOKUP(B10,[2]Hoja1!$C$2:$E$279,3,FALSE) -> 1356 | G10: =D10*F10 -> 8.371944 | K10: =$K$4*E10% -> 0.006174
B11: 1210010 | C11: CLORURO DE POTASIO - KCL | D11: 0.004090275 | E11: 0.53 | F11: =VLOOKUP(B11,[2]Hoja1!$C$2:$E$279,3,FALSE) -> 11600 | G11: =D11*F11 -> 47.44719 | H11: 16100 | I11: =H11*D11 -> 65.853427 | J11: =((F11/H11)*100)-100 -> -27.950311 | K11: =$K$4*E11% -> 0.004090275 | L11: =$L$4*E11 -> 1065.8565
B12: =VLOOKUP(C12,[1]Hoja1!$B$2:$C$260,2,FALSE) -> 1210004 | C12: SAL CURANTE AL 12 % | D12: 0.0012348 | E12: 0.16 | F12: =VLOOKUP(B12,[2]Hoja1!$C$2:$E$279,3,FALSE) -> 3841 | G12: =D12*F12 -> 4.7428668 | H12: 19145.99 | I12: =H12*D12 -> 23.641468 | J12: =((F12/H12)*100)-100 -> -79.938358 | K12: =$K$4*E12% -> 0.0012348 | L12: =$L$4*E12 -> 321.768
B13: =VLOOKUP(C13,[1]Hoja1!$B$2:$C$260,2,FALSE) -> 121007 | C13: SUPRA MEAT F451 | D13: 0.00038375475 | E13: 0.049725268 | F13: =VLOOKUP(B13,[2]Hoja1!$C$2:$E$279,3,FALSE) -> 16905 | G13: =D13*F13 -> 6.4873741 | H13: 20299 | I13: =H13*D13 -> 7.7898378 | J13: =((F13/H13)*100)-100 -> -16.720035 | K13: =$K$4*E13% -> 0.00038375475 | L13: =$L$4*E13 -> 100
B14: =VLOOKUP(C14,[1]Hoja1!$B$2:$C$260,2,FALSE) -> 1230003 | C14: PREPARADO SABOR CERVECERO NEO | D14: 0.010791184 | E14: 1.3982745 | F14: =VLOOKUP(B14,[2]Hoja1!$C$2:$E$279,3,FALSE) -> 20099.99 | G14: =D14*F14 -> 216.90268 | H14: 17430 | I14: =H14*D14 -> 188.09033 | J14: =((F14/H14)*100)-100 -> 15.318359 | K14: =$K$4*E14% -> 0.010791184 | L14: =$L$4*E14 -> 2812
B15: =VLOOKUP(C15,[1]Hoja1!$B$2:$C$260,2,FALSE) -> 1220009 | C15: CEBOLLA EN POLVO | D15: 0.00038375475 | E15: 0.049725268 | F15: =VLOOKUP(B15,[2]Hoja1!$C$2:$E$279,3,FALSE) -> 21312.16 | G15: =D15*F15 -> 8.1786427 | H15: 9565.21 | I15: =H15*D15 -> 3.6706948 | J15: =((F15/H15)*100)-100 -> 122.80912 | K15: =$K$4*E15% -> 0.00038375475 | L15: =$L$4*E15 -> 100
B16: =VLOOKUP(C16,[1]Hoja1!$B$2:$C$260,2,FALSE) -> 1220005 | C16: AJO MOLIDO DESHIDRATADO B.1 | D16: 0.00038375475 | E16: 0.049725268 | F16: =VLOOKUP(B16,[2]Hoja1!$C$2:$E$279,3,FALSE) -> 17429.99 | G16: =D16*F16 -> 6.6888415 | H16: 4500 | I16: =H16*D16 -> 1.7268964 | J16: =((F16/H16)*100)-100 -> 287.33311 | K16: =$K$4*E16% -> 0.00038375475 | L16: =$L$4*E16 -> 100
B17: =VLOOKUP(C17,[1]Hoja1!$B$2:$C$260,2,FALSE) -> 1260009 | C17: PROTEINA CONCENTRADA DE SOYA 70% | D17: 0.03070038 | E17: 3.9780214 | F17: =VLOOKUP(B17,[2]Hoja1!$C$2:$E$279,3,FALSE) -> 7033.69 | G17: =D17*F17 -> 215.93696 | H17: 12278.37 | I17: =H17*D17 -> 376.95063 | J17: =((F17/H17)*100)-100 -> -42.71479 | K17: =$K$4*E17% -> 0.03070038 | L17: =$L$4*E17 -> 8000
B18: =VLOOKUP(C18,[1]Hoja1!$B$2:$C$260,2,FALSE) -> 1260011 | C18: ALMIDON DE PAPA | D18: 0.067528125 | E18: 8.75 | F18: =VLOOKUP(B18,[2]Hoja1!$C$2:$E$279,3,FALSE) -> 4450.01 | G18: =D18*F18 -> 300.50083 | H18: 53849.37 | I18: =H18*D18 -> 3636.347 | J18: =((F18/H18)*100)-100 -> -91.736189 | K18: =$K$4*E18% -> 0.067528125 | L18: =$L$4*E18 -> 17596.688
B19: =VLOOKUP(C19,[1]Hoja1!$B$2:$C$260,2,FALSE) -> 1270009 | C19: HUMO TRUSMOKE DRY x 20 KG | D19: 0.00072913403 | E19: 0.094478009 | F19: =VLOOKUP(B19,[2]Hoja1!$C$2:$E$279,3,FALSE) -> 57046.53 | G19: =D19*F19 -> 41.594567 | I19: =#REF!*D19 -> #REF! | J19: =((F19/#REF!)*100)-100 -> #REF! | K19: =$K$4*E19% -> 0.00072913403 | L19: =$L$4*E19 -> 190
B20: TOTAL | D20: =SUM(D5:D19) -> 0.77190396 | E20: =SUM(E5:E19) -> 100.01995 | G20: =SUM(G5:G19) -> 2979.9301 | I20: =SUM(I5:I19) -> #REF! | J20: =((G20/I20)*100)-100 -> #REF! | L20: =SUM(L5:L19) -> 199536.28
B22: MERMAS | D22: =+C25+(C25*C31%) -> 771.75
B23: Linea | C23: Salchichones
B24: Referencia | C24: Salchichón Cervecero Faizán
B25: Presentación en Gramos | C25: 750
B26: Máquina | C26: 0
B27: Cocción | C27: 0.3
B28: Frío | C28: 0.3
B29: Recorte | C29: 0.3
B30: Sobrepeso | C30: 2
B31: Merma Total | C31: =C30+C29+C28+C27 -> 2.9
B33: MATERIAL DE EMPAQUE
B34: CÓDIGO | C34: DESCRIPCIÓN | D34: CATIDAD | E34: =+'CIF Y PV'!$F$4 -> JUN-COP/UMB | F34: =+'CIF Y PV'!$G$4 -> JUN-COP/APP | G34: =+'CIF Y PV'!$H$4 -> MAY-COP/UMB | H34: =+'CIF Y PV'!$I$4 -> MAY-COP/APP | I34: % | J34: 14931
B35: 1380005 | C35: GRAPAS POLY- R-ID M 07-150 | D35: 2 | E35: =VLOOKUP(B35,[2]Hoja1!$C$2:$E$279,3,FALSE) -> 29.02 | F35: =D35*E35 -> 58.04 | G35: 31.68 | H35: =G35*D35 -> 63.36 | I35: =((E35/G35)*100)-100 -> -8.3964646 | J35: =J34*D35 -> 29862
B36: 1380003 | C36: LAZOS POLY-CLIP GSA20 | D36: 1 | E36: =VLOOKUP(B36,[2]Hoja1!$C$2:$E$279,3,FALSE) -> 56.19 | F36: =D36*E36 -> 56.19 | G36: 57.87 | H36: =G36*D36 -> 57.87 | I36: =((E36/G36)*100)-100 -> -2.9030586 | J36: =J34*D36 -> 14931
B37: 1370015 | C37: TUBU SALCHICHON CERVECERO FAIZAN 750G | D37: 0.39 | E37: =VLOOKUP(B37,[2]Hoja1!$C$2:$E$279,3,FALSE) -> 552.94 | F37: =D37*E37 -> 215.6466 | G37: 555.72 | H37: =G37*D37 -> 216.7308 | I37: =((E37/G37)*100)-100 -> -0.50025193 | J37: =J34*D37 -> 5823.09
C38: TOTAL | F38: =SUM(F35:F37) -> 329.8766 | H38: =SUM(H35:H37) -> 337.9608 | I38: =((F38/H38)*100)-100 -> -2.3920526
H39: =+'CIF Y PV'!$G$1 -> MAYO
B40: TOTAL INSUMOS (UND 750 G) | H40: =+F38+G20 -> 3309.8067
B41: ASIGNACIÓN MOD/CIF | H41: =+('CIF Y PV'!C3/1000)*750 -> 1417.5
B42: TOTAL COSTO POR UND (750) | H42: =+H41+H40 -> 4727.3067
B43: PRECIO DE VENTA | H43: ='CIF Y PV'!C58 -> 11287.901
...

Sheet CERVECERO 1300
B2: CERVECERO FAIZAN X 1300 G
B4: CÓDIGO | C4: DESCRIPCIÓN | D4: CATIDAD | E4: % | F4: =+'CIF Y PV'!$F$2 -> JUN-COP/Kg | G4: =+'CIF Y PV'!$G$2 -> JUN-COP/APP | H4: =+'CIF Y PV'!$H$2 -> MAY-COP/Kg | I4: =+'CIF Y PV'!$I$2 -> MAY-COP/APP | J4: % | K4: =+D22/1000 -> 1.3286
B5: =VLOOKUP(C5,[1]Hoja1!$B$2:$C$260,2,FALSE) -> 1112001 | C5: PASTA DE POLLO IMPORTADA PREMIUM | D5: 0.46514286 | E5: 35.01 | F5: =VLOOKUP(B5,[2]Hoja1!$C$2:$E$279,3,FALSE) -> 3663.96 | G5: =D5*F5 -> 1704.2648 | H5: 4222.72 | I5: =H5*D5 -> 1964.1681 | J5: =((F5/H5)*100)-100 -> -13.232229 | K5: =$K$4*E5% -> 0.46514286
B6: =VLOOKUP(C6,[1]Hoja1!$B$2:$C$260,2,FALSE) -> 1121009 | C6: TOCINO NACIONAL | D6: 0.05819268 | E6: 4.38 | F6: =VLOOKUP(B6,[2]Hoja1!$C$2:$E$279,3,FALSE) -> 8741.62 | G6: =D6*F6 -> 508.6983 | H6: 2033.73 | I6: =H6*D6 -> 118.3482 | J6: =((F6/H6)*100)-100 -> 329.83189 | K6: =$K$4*E6% -> 0.05819268
B7: =VLOOKUP(C7,[1]Hoja1!$B$2:$C$260,2,FALSE) -> 1122007 | C7: RECORTE DE CERDO 80/20 IMPORTADO | D7: 0.10642086 | E7: 8.01 | F7: =VLOOKUP(B7,[2]Hoja1!$C$2:$E$279,3,FALSE) -> 11229.33 | G7: =D7*F7 -> 1195.035 | H7: 0 | I7: =H7*D7 -> 0 | J7: =((F7/H7)*100)-100 -> #DIV/0! | K7: =$K$4*E7% -> 0.10642086
B8: =VLOOKUP(C8,[1]Hoja1!$B$2:$C$260,2,FALSE) -> 2906001 | C8: EMULSION DE PIEL DE CERDO | D8: 0.126217 | E8: 9.5 | F8: =VLOOKUP(B8,[2]Hoja1!$C$2:$E$279,3,FALSE) -> 1956.71 | G8: =D8*F8 -> 246.97007 | H8: 8910.1 | I8: =H8*D8 -> 1124.6061 | J8: =((F8/H8)*100)-100 -> -78.039416 | K8: =$K$4*E8% -> 0.126217
B9: =VLOOKUP(C9,[1]Hoja1!$B$2:$C$260,2,FALSE) -> 1131002 | C9: AGUA POTABLE | D9: 0.36217636 | E9: 27.26 | F9: =VLOOKUP(B9,[2]Hoja1!$C$2:$E$279,3,FALSE) -> 0 | G9: =D9*F9 -> 0 | H9: 3508.01 | I9: =H9*D9 -> 1270.5183 | J9: =((F9/H9)*100)-100 -> -100 | K9: =$K$4*E9% -> 0.36217636
B10: 1210005 | C10: SAL YODADA REFISAL | D10: 0.0106288 | E10: 0.8 | F10: =VLOOKUP(B10,[2]Hoja1!$C$2:$E$279,3,FALSE) -> 1356 | G10: =D10*F10 -> 14.412653 | H10: 3508.01 | K10: =$K$4*E10% -> 0.0106288
B11: 1210010 | C11: CLORURO DE POTASIO - KCL | D11: 0.00704158 | E11: 0.53 | F11: =VLOOKUP(B11,[2]Hoja1!$C$2:$E$279,3,FALSE) -> 11600 | G11: =D11*F11 -> 81.682328 | H11: 16100 | I11: =H11*D11 -> 113.36944 | J11: =((F11/H11)*100)-100 -> -27.950311 | K11: =$K$4*E11% -> 0.00704158
B12: =VLOOKUP(C12,[1]Hoja1!$B$2:$C$260,2,FALSE) -> 1210004 | C12: SAL CURANTE AL 12 % | D12: 0.00212576 | E12: 0.16 | F12: =VLOOKUP(B12,[2]Hoja1!$C$2:$E$279,3,FALSE) -> 3841 | G12: =D12*F12 -> 8.1650442 | H12: 19145.99 | I12: =H12*D12 -> 40.69978 | J12: =((F12/H12)*100)-100 -> -79.938358 | K12: =$K$4*E12% -> 0.00212576
B13: =VLOOKUP(C13,[1]Hoja1!$B$2:$C$260,2,FALSE) -> 121007 | C13: SUPRA MEAT F451 | D13: 0.00066064991 | E13: 0.049725268 | F13: =VLOOKUP(B13,[2]Hoja1!$C$2:$E$279,3,FALSE) -> 16905 | G13: =D13*F13 -> 11.168287 | H13: 20299 | I13: =H13*D13 -> 13.410533 | J13: =((F13/H13)*100)-100 -> -16.720035 | K13: =$K$4*E13% -> 0.00066064991
B14: =VLOOKUP(C14,[1]Hoja1!$B$2:$C$260,2,FALSE) -> 1230003 | C14: PREPARADO SABOR CERVECERO NEO | D14: 0.018577475 | E14: 1.3982745 | F14: =VLOOKUP(B14,[2]Hoja1!$C$2:$E$279,3,FALSE) -> 20099.99 | G14: =D14*F14 -> 373.40707 | H14: 17430 | I14: =H14*D14 -> 323.8054 | J14: =((F14/H14)*100)-100 -> 15.318359 | K14: =$K$4*E14% -> 0.018577475
B15: =VLOOKUP(C15,[1]Hoja1!$B$2:$C$260,2,FALSE) -> 1220009 | C15: CEBOLLA EN POLVO | D15: 0.00066064991 | E15: 0.049725268 | F15: =VLOOKUP(B15,[2]Hoja1!$C$2:$E$279,3,FALSE) -> 21312.16 | G15: =D15*F15 -> 14.079877 | H15: 9565.21 | I15: =H15*D15 -> 6.3192551 | J15: =((F15/H15)*100)-100 -> 122.80912 | K15: =$K$4*E15% -> 0.00066064991
B16: =VLOOKUP(C16,[1]Hoja1!$B$2:$C$260,2,FALSE) -> 1220005 | C16: AJO MOLIDO DESHIDRATADO B.1 | D16: 0.00066064991 | E16: 0.049725268 | F16: =VLOOKUP(B16,[2]Hoja1!$C$2:$E$279,3,FALSE) -> 17429.99 | G16: =D16*F16 -> 11.515121 | H16: 4500 | I16: =H16*D16 -> 2.9729246 | J16: =((F16/H16)*100)-100 -> 287.33311 | K16: =$K$4*E16% -> 0.00066064991
B17: =VLOOKUP(C17,[1]Hoja1!$B$2:$C$260,2,FALSE) -> 1260009 | C17: PROTEINA CONCENTRADA DE SOYA 70% | D17: 0.052851993 | E17: 3.9780214 | F17: =VLOOKUP(B17,[2]Hoja1!$C$2:$E$279,3,FALSE) -> 7033.69 | G17: =D17*F17 -> 371.74453 | H17: 12278.37 | I17: =H17*D17 -> 648.93632 | J17: =((F17/H17)*100)-100 -> -42.71479 | K17: =$K$4*E17% -> 0.052851993
B18: =VLOOKUP(C18,[1]Hoja1!$B$2:$C$260,2,FALSE) -> 1260011 | C18: ALMIDON DE PAPA | D18: 0.1162525 | E18: 8.75 | F18: =VLOOKUP(B18,[2]Hoja1!$C$2:$E$279,3,FALSE) -> 4450.01 | G18: =D18*F18 -> 517.32479 | H18: 53849.37 | I18: =H18*D18 -> 6260.1239 | J18: =((F18/H18)*100)-100 -> -91.736189 | K18: =$K$4*E18% -> 0.1162525
B19: =VLOOKUP(C19,[1]Hoja1!$B$2:$C$260,2,FALSE) -> 1270009 | C19: HUMO TRUSMOKE DRY x 20 KG | D19: 0.0012552348 | E19: 0.094478009 | F19: =VLOOKUP(B19,[2]Hoja1!$C$2:$E$279,3,FALSE) -> 57046.53 | G19: =D19*F19 -> 71.606791 | H19: 8850.84 | I19: =H19*D19 -> 11.109883 | J19: =((F19/H19)*100)-100 -> 544.53238 | K19: =$K$4*E19% -> 0.0012552348
B20: TOTAL | D20: =SUM(D5:D19) -> 1.3288651 | E20: =SUM(E5:E19) -> 100.01995 | G20: =SUM(G5:G19) -> 5130.0746 | I20: =SUM(I5:I19) -> 11898.388 | J20: =((G20/I20)*100)-100 -> -56.884289
B22: MERMAS | D22: =+C25+(C25*C31%) -> 1328.6
B23: Linea | C23: Salchichones
B24: Referencia | C24: Salchichón Cervecero Faizán
B25: Presentación en Gramos | C25: 1300
B26: Máquina | C26: 0
B27: Cocción | C27: 0.5
B28: Frío | C28: 0.5
B29: Recorte | C29: 0.5
B30: Sobrepeso | C30: 0.7
B31: Merma Total | C31: =C30+C29+C28+C27 -> 2.2
B33: MATERIAL DE EMPAQUE
B34: CÓDIGO | C34: DESCRIPCIÓN | D34: CATIDAD | E34: =+'CIF Y PV'!$F$4 -> JUN-COP/UMB | F34: =+'CIF Y PV'!$G$4 -> JUN-COP/APP | G34: =+'CIF Y PV'!$H$4 -> MAY-COP/UMB | H34: =+'CIF Y PV'!$I$4 -> MAY-COP/APP | I34: % | J34: 4119
